Workbook

Sheet 00_Metadaten
A1: Herkunftsnachweis
A2: Quelle | B2: https://raw.githubusercontent.com/BSI-Bund/Stand-der-Technik-Bibliothek/main/control_layer/Grundschutz++/Grundschutz++-resolved_catalog.json
A3: Git-Commit (SHA) | B3: f0edb1b9f67323264d463894bf051d498e526764
A4: Commit-Datum | B4: 2026-08-13T09:44:11Z
A5: SHA-256 der Quelldatei | B5: 29607ac0d3921c83af4c5435335f59c072b8d7be35e1818175dc3f92c59ac6e9
A6: Abgerufen am (UTC) | B6: 2026-08-19T14:31:58.337599+00:00
A8: Katalog
A9: Katalog-UUID | B9: 863756dc-231a-4513-9047-1e44d1841861
A10: Katalog-Version | B10: 2026-08-13T09:23:10.047565+00:00
A11: Zuletzt geaendert (BSI) | B11: 2026-08-13T09:23:18.897718476Z
A12: OSCAL-Version | B12: 1.1.3
A13: Anzahl Anforderungen | B13: 1000
A15: Erzeugung
A16: Werkzeug-Version | B16: 0.1.0

Sheet Deckblatt
B1: Einstufung gemäß Vorgaben der Sicherheitskonzeption
B3: Dokumententitel | C3: Praktiken und Grundschutz++-Checks
B4: Layout | C4: BSI-Vorlage A.3.4, Kompendium-Edition 2023
B5: Katalog | C5: Grundschutz++ (OSCAL), Anwenderkatalog des BSI
B6: Katalog-Version | C6: 2026-08-13T09:23:10.047565+00:00
B7: Git-Commit | C7: f0edb1b9f67323264d463894bf051d498e526764
B8: SHA-256 der Quelldatei | C8: 29607ac0d3921c83af4c5435335f59c072b8d7be35e1818175dc3f92c59ac6e9
B9: Erzeugt am (UTC) | C9: 2026-08-19T14:31:58.337599+00:00
B10: Werkzeug | C10: gspp-tool 0.1.0
B12: Anforderungszeilen | C12: 652
B13: Teilanforderungen (bewertbar) | C13: 974
B15: Zuordnung zu IT-Grundschutz 2023
B16: Quelle | C16: Offizielles BSI-Mapping (control_layer/Mappings/IT-GS2023-zu-GSpp)
B17: Abdeckung | C17: Unvollstaendig, laut BSI noch in Pilotierung - nur ca. 30% der GS++-Anforderungen haben aktuell eine Zuordnung. Leere Spalten 'Alte Anforderung' bedeuten 'noch nicht kartiert', nicht 'keine Beziehung'.
B19: Spalten ein-/ausblenden
B20: Bedienung | C20: Alle 25 Spalten sind beim Öffnen sichtbar. Über den Spaltenköpfen stehen kleine +/− Schaltflächen, mit denen sich zwei Blöcke unabhängig einklappen lassen: 'Zuordnung IT-GS 2023' (Spalten N–O) und 'Guidance' (Spalten P–Y: Erläuterung, Zielobjekte, Dokumentation, Ergebnis, Gefährdungen, Aufwand, vier Schutzziele). Keine Makros nötig.
B21: Schwerpunkt (Schutzziel) | C21: Nennt nur Schutzziele mit Wert 2 – also jene, die laut BSI im Zentrum der Anforderung stehen. Leer heißt: kein Schutzziel besonders betont (gilt für rund die Hälfte der Anforderungen). Die Einzelwerte 0/1/2 stehen im Guidance-Block.
B23: Offene fachliche Annahme
B24: Spalte 'Schutz' | C24: GS++ kennt zwei Schutzbedarfsstufen, die 2023er-Vorlage drei Anforderungskategorien. Abgebildet wird: erhöht -> erhöhter Schutzbedarf; normal-SdT + MUSS -> Basis; normal-SdT + SOLLTE/KANN -> Standard. Diese Zuordnung ist nicht vom BSI dokumentiert und fachlich zu bestätigen.

Sheet ARCH
A1: Einstufung gemäß Vorgaben der Sicherheitskonzeption
A3: ARCH | B3: Architektur
A4: Zielobjekte | B4: =IF('Praktiken'!D5="","",'Praktiken'!D5)
A5: Zuständig | B5: =IF('Praktiken'!S5="","",'Praktiken'!S5)
A6: Anforderung | B6: Beschreibung | C6: Teilanforderung | D6: Schutz | E6: Anforderungstext | F6: Umsetzung | G6: Nachweis | H6: Status | I6: Maßnahme | J6: Befragte Person | K6: Prüfende Person | L6: Datum der Prüfung | M6: Schwerpunkt (Schutzziel) | N6: Alte Anforderung (IT-GS 2023) | O6: Beziehung (IT-GS 2023) | P6: Erläuterung | Q6: Zielobjekt-Kategorien | R6: Dokumentation | S6: Ergebnis | T6: Gefährdungen | U6: Aufwand | V6: Vertraulichkeit | W6: Integrität | X6: Verfügbarkeit | Y6: Authentizität
A7: ARCH.1.1 | B7: Verfahren und Regelungen | D7: Basis-Anforderungen | E7: Gesamt: | H7: =IF(OR(COUNTBLANK($H$8:$H$10)>0,COUNTIF($H$8:$H$10,"unbearbeitet")=COUNTA($H$8:$H$10)),"Bitte Teilanforderungen ausfüllen",IF(COUNTIF($H$8:$H$10,"zu klären")>0,"zu klären",IF(COUNTIF($H$8:$H$10,"entbehrlich")=COUNTA($H$8:$H$10),"entbehrlich",IF(COUNTIF($H$8:$H$10,"verwiesen")=COUNTA($H$8:$H$10),"verwiesen",IF(COUNTIF($H$8:$H$10,"nein")+COUNTIF($H$8:$H$10,"entbehrlich")=COUNTA($H$8:$H$10),"nein",IF(COUNTIF($H$8:$H$10,"ja")+COUNTIF($H$8:$H$10,"entbehrlich")+COUNTIF($H$8:$H$10,"verwiesen")=COUNTA($H$8:$H$10),"ja","teilweise")))))) | N7: APP.3.6.A1-UA.2; INF.14.A13-UA.2; NET.1.1.A1-UA.1; NET.1.1.A13-UA.1; NET.1.1.A16-UA.1; NET.1.1.A17-UA.1; NET.1.1.A2-UA.4; NET.1.1.A2-UA.5; NET.1.1.A25-UA.1; NET.1.1.A3-UA.1; NET.1.1.A3-UA.3; NET.1.2.A1-UA.1; NET.1.2.A11-UA.1; NET.1.2.A11-UA.9; NET.1.2.A12-UA.1; NET.1.2.A14-UA.2; NET.1.2.A15-UA.1; OPS.1.1.1.A15-UA.3 | O7: subset-of; subset-of; subset-of; subset-of; subset-of; subset-of; subset-of; subset-of; subset-of; subset-of; subset-of; subset-of; subset-of; subset-of; subset-of; subset-of; subset-of; subset-of | P7: Die Netzarchitektur ist der strukturierte Entwurf einer Netzinfrastruktur, einschließlich der IT-Systeme und verbundsbezogenen Schutzmechanismen darin. Hierzu gehören die Segmentierung und Filterung von kabelgebundenen und kabellosen Netzen, Netzmanagement sowie die Redundanz wichtiger Systeme für eine ausreichende Gewährleistung der Verfügbarkeit. Die bei der Festlegung des Verfahrens im Einzelnen zu berücksichtigenden Inhalte ergeben sich aus den Anforderungen dieser Praktik. Empfehlenswert ist ein Design des Netzes nach dem Zero-Trust-Prinzip (siehe BSI Positionspapier Zero-Trust). Dennoch sind Netzgrenzen zur Isolierung durch Filterung oder Zugbrücken bei Angriffen weiterhin sinnvoll. Weitere Informationen zur Absicherung von Netzen sind in ISO/IEC 27033 zu finden. | S7: Verfahren und Regelungen zur Architektur des Netzes und damit verbundener Infrastrukturen | T7: G 0.18 – Fehlplanung oder fehlende Anpassung; G 0.29 – Verstoß gegen Gesetze oder Regelungen; G 0.30 – Unberechtigte Nutzung oder Administration von Geräten und Systemen | U7: 0 | V7: 1 | W7: 1 | X7: 1 | Y7: 1
A8: ARCH.1.1 | B8: Verfahren und Regelungen | C8: ARCH.1.1.1 | D8: Basis-Anforderungen | E8: Architektur MUSS die Verfahren und Regelungen dokumentieren. | H8: unbearbeitet | M8: Vertraulichkeit, Integrität | N8: CON.8.A12-UA.4; INF.12.A10-UA.1; INF.12.A10-UA.2; INF.12.A10-UA.6; INF.12.A10-UA.8; INF.13.A3-UA.4; ISMS.1.A12-UA.6; NET.1.1.A2-UA.1; NET.1.1.A2-UA.3 | O8: subset-of; subset-of; subset-of; subset-of; subset-of; subset-of; subset-of; equivalent-to; subset-of | P8: Ohne eine Dokumentation könnte die Einhaltung der Verfahren und Regelungen von der Tagesform oder dem individuellen Wissen einzelner Mitarbeiter abhängen, was zu inkonsistenten Entscheidungen und Fehlern führen könnte; insbesondere beim Ausscheiden eines langjährigen Administrators könnte wertvolles prozessuales Wissen verloren gehen. Eine klare Dokumentation sichert die Verbindlichkeit und Wiederholbarkeit und dient als unverzichtbare Grundlage für die Einarbeitung neuer Kollegen, für die Durchführung von Audits und zur einheitlichen Anwendung der Regeln in der gesamten Institution. Die Dokumentation kann in einem eigenständigen Dokument als Richtlinie erfolgen, aber auch als Abschnitt in einem bereits bestehenden Dokument oder über die digital strukturierte Erfassung von Maßnahmen zur Umsetzung der Anforderungen, etwa über eine Software zum Management der Informationssicherheit. Sinnvoll ist es, Ort und Struktur der Dokumentation an der jeweiligen Zielgruppe, d.h. den für das Management und die Umsetzung verantwortlichen Personen oder Rollen, auszurichten. | R8: IT-Betriebskonzept | S8: die Verfahren und Regelungen | T8: G 0.18 – Fehlplanung oder fehlende Anpassung; G 0.37 – Abstreiten von Handlungen; G 0.29 – Verstoß gegen Gesetze oder Regelungen | U8: 0 | V8: 2 | W8: 2 | X8: 1 | Y8: 1
A9: ARCH.1.1 | B9: Verfahren und Regelungen | C9: ARCH.1.1.2 | D9: Basis-Anforderungen | E9: Architektur MUSS die mit den Verfahren und Regelungen verbundenen Aufgaben zuständigen Personen oder Rollen zuweisen. | H9: unbearbeitet | N9: ISMS.1.A6-UA.7; OPS.1.1.1.A1-UA.1; OPS.1.1.1.A1-UA.2; OPS.1.1.1.A19-UA.3; ORP.1.A1-UA.1; ORP.1.A2-UA.1; ORP.1.A4-UA.1 | O9: intersects-with; equivalent-to; intersects-with; subset-of; intersects-with; intersects-with; intersects-with | P9: Die Zuweisung von Aufgaben bezeichnet die eindeutige und verbindliche Übertragung von konkreten Tätigkeiten und Verantwortlichkeiten des Änderungsprozesses, wie etwa die Risikobewertung, die technische Umsetzung oder die finale Freigabe, an definierte Stellen in der Institution. Der Sinn dieser Vorschrift ist es, die Verantwortlichkeit ("Accountability") für jeden einzelnen Schritt im Prozess klarzustellen. Ohne eine solche Zuweisung könnten kritische Prüfungen unterbleiben, weil sich niemand explizit zuständig fühlt, was wiederum die Wahrscheinlichkeit fehlgeschlagener Änderungen erhöht. Eine klare Regelung kann sicherstellen, dass keine Aufgaben übersehen werden und jede Tätigkeit von einer dafür qualifizierten und befugten Stelle ausgeführt wird, was die Prozesssicherheit signifikant erhöht. Eine bewährte Methode zur Umsetzung ist die Erstellung einer RACI-Matrix (Responsible, Accountable, Consulted, Informed), die tabellarisch für jeden Prozessschritt darstellt, wer für die Durchführung verantwortlich ist, wer die Gesamtverantwortung trägt, wer zu konsultieren und wer zu informieren ist. Diese Zuständigkeiten können auch direkt in einem Workflow- oder Ticketsystem abgebildet werden, sodass Aufgaben, wie beispielsweise Genehmigungsschritte, automatisch an die richtige Gruppe oder Person weitergeleitet werden. Sinnvoll ist es, die Zuweisung anhand von Rollen (z. B. "Anwendungsverantwortlicher", "Netzwerkadministrator", "Change Manager") vorzunehmen, statt an konkrete Personen. Dieser Ansatz stellt sicher, dass die Prozesse auch bei Personalwechseln stabil weiterlaufen, da die Zuständigkeit an die Funktion und nicht an das Individuum gebunden ist. | R9: Geschäftsverteilungsplan | S9: die mit den Verfahren und Regelungen verbundenen Aufgaben | T9: G 0.18 – Fehlplanung oder fehlende Anpassung; G 0.31 – Fehlerhafte Nutzung oder Administration von Geräten und Systemen | U9: 0 | V9: 1 | W9: 1 | X9: 1 | Y9: 0
A10: ARCH.1.1 | B10: Verfahren und Regelungen | C10: ARCH.1.1.3 | D10: Basis-Anforderungen | E10: Architektur MUSS die zuständigen Personen oder Rollen über die Verfahren und Regelungen informieren. | H10: unbearbeitet | N10: ISMS.1.A8-UA.6; NET.1.2.A11-UA.2; NET.3.2.A1-UA.3; ORP.1.A1-UA.4; ORP.2.A1-UA.2 | O10: subset-of; equivalent-to; subset-of; equivalent-to; equivalent-to | P10: Wenn die Zuständigen die etablierten Verfahren nicht kennen, besteht die Gefahr, dass diese – sei es aus Unwissenheit oder Bequemlichkeit – umgangen werden, was die Schutzwirkung des gesamten Managementsystems untergräbt. So könnte ein neuer Systemadministrator eine weitreichende Konfigurationsänderung vornehmen, ohne den vorgeschriebenen Genehmigungsprozess zu durchlaufen, was zu einem unbemerkten Sicherheitsrisiko führen könnte. Eine gezielte Information kann hingegen die Akzeptanz der Regelungen fördern und sicherstellen, dass alle Beteiligten ihre Rolle im Prozess verstehen und die Abläufe korrekt anwenden. Zur Umsetzung ist es sinnvoll, die Dokumentation im Rahmen eines Onboarding-Prozesses bekanntzugeben und bei allen Änderungen eine automatische Benachrichtigung aller zuständigen Personen oder Rollen anzustoßen. | R10: IT-Betriebskonzept | S10: die zuständigen Personen oder Rollen über die Verfahren und Regelungen | T10: G 0.18 – Fehlplanung oder fehlende Anpassung; G 0.29 – Verstoß gegen Gesetze oder Regelungen | U10: 0 | V10: 1 | W10: 1 | X10: 1 | Y10: 0
A11: ARCH.1.2 | B11: Regelmäßige Überprüfung | D11: Basis-Anforderungen | E11: Gesamt: | H11: =IF(OR(COUNTBLANK($H$12:$H$12)>0,COUNTIF($H$12:$H$12,"unbearbeitet")=COUNTA($H$12:$H$12)),"Bitte Teilanforderungen ausfüllen",IF(COUNTIF($H$12:$H$12,"zu klären")>0,"zu klären",IF(COUNTIF($H$12:$H$12,"entbehrlich")=COUNTA($H$12:$H$12),"entbehrlich",IF(COUNTIF($H$12:$H$12,"verwiesen")=COUNTA($H$12:$H$12),"verwiesen",IF(COUNTIF($H$12:$H$12,"nein")+COUNTIF($H$12:$H$12,"entbehrlich")=COUNTA($H$12:$H$12),"nein",IF(COUNTIF($H$12:$H$12,"ja")+COUNTIF($H$12:$H$12,"entbehrlich")+COUNTIF($H$12:$H$12,"verwiesen")=COUNTA($H$12:$H$12),"ja","teilweise")))))) | N11: INF.11.A4-UA.4; INF.13.A4-UA.4; ISMS.1.A11-UA.2; ISMS.1.A7-UA.3; NET.2.2.A1-UA.7; NET.3.2.A1-UA.5; ORP.1.A1-UA.3 | O11: intersects-with; intersects-with; intersects-with; intersects-with; subset-of; subset-of; superset-of | P11: Eine geplante Überprüfung der etablierten Verfahren und Regelungen dient dazu festzustellen, ob diese noch wirksam, effizient und an die aktuellen Gegebenheiten angepasst sind. Eine anlassbezogene Überprüfung wird durch spezifische Ereignisse ausgelöst, wie etwa einen schwerwiegenden Sicherheitsvorfall, eine strategische Neuausrichtung der IT oder neue gesetzliche Anforderungen. Der Zweck dieser Anforderung ist es, die kontinuierliche Verbesserung und Anpassungsfähigkeit des Prozesses sicherzustellen, da veraltete Regelungen neuen technologischen Entwicklungen oder Bedrohungen nicht mehr gerecht werden könnten; ein vor Jahren für monolithische Anwendungen konzipierter Prozess ist beispielsweise für agile Entwicklungsmethoden oder Microservice-Architekturen ungeeignet. Die regelmäßige Überprüfung kann die Effektivität des Sicherheitsmanagements langfristig aufrechterhalten und die Resilienz der Institution stärken. | R11: Übungs- und Prüfplan | S11: die Verfahren und Regelungen | T11: G 0.18 – Fehlplanung oder fehlende Anpassung; G 0.29 – Verstoß gegen Gesetze oder Regelungen; G 0.31 – Fehlerhafte Nutzung oder Administration von Geräten und Systemen | U11: 0 | V11: 1 | W11: 1 | X11: 1 | Y11: 0
A12: ARCH.1.2 | B12: Regelmäßige Überprüfung | C12: ARCH.1.2 | D12: Basis-Anforderungen | E12: Architektur MUSS die Verfahren und Regelungen regelmäßig und anlassbezogen auf Aktualität überprüfen. | H12: unbearbeitet | N12: INF.11.A4-UA.4; INF.13.A4-UA.4; ISMS.1.A11-UA.2; ISMS.1.A7-UA.3; NET.2.2.A1-UA.7; NET.3.2.A1-UA.5; ORP.1.A1-UA.3 | O12: intersects-with; intersects-with; intersects-with; intersects-with; subset-of; subset-of; superset-of | P12: Eine geplante Überprüfung der etablierten Verfahren und Regelungen dient dazu festzustellen, ob diese noch wirksam, effizient und an die aktuellen Gegebenheiten angepasst sind. Eine anlassbezogene Überprüfung wird durch spezifische Ereignisse ausgelöst, wie etwa einen schwerwiegenden Sicherheitsvorfall, eine strategische Neuausrichtung der IT oder neue gesetzliche Anforderungen. Der Zweck dieser Anforderung ist es, die kontinuierliche Verbesserung und Anpassungsfähigkeit des Prozesses sicherzustellen, da veraltete Regelungen neuen technologischen Entwicklungen oder Bedrohungen nicht mehr gerecht werden könnten; ein vor Jahren für monolithische Anwendungen konzipierter Prozess ist beispielsweise für agile Entwicklungsmethoden oder Microservice-Architekturen ungeeignet. Die regelmäßige Überprüfung kann die Effektivität des Sicherheitsmanagements langfristig aufrechterhalten und die Resilienz der Institution stärken. | R12: Übungs- und Prüfplan | S12: die Verfahren und Regelungen | T12: G 0.18 – Fehlplanung oder fehlende Anpassung; G 0.29 – Verstoß gegen Gesetze oder Regelungen; G 0.31 – Fehlerhafte Nutzung oder Administration von Geräten und Systemen | U12: 0 | V12: 1 | W12: 1 | X12: 1 | Y12: 0
A13: ARCH.2.1 | B13: Netzsegmente | D13: Standard-Anforderungen | E13: Gesamt: | H13: =IF(OR(COUNTBLANK($H$14:$H$14)>0,COUNTIF($H$14:$H$14,"unbearbeitet")=COUNTA($H$14:$H$14)),"Bitte Teilanforderungen ausfüllen",IF(COUNTIF($H$14:$H$14,"zu klären")>0,"zu klären",IF(COUNTIF($H$14:$H$14,"entbehrlich")=COUNTA($H$14:$H$14),"entbehrlich",IF(COUNTIF($H$14:$H$14,"verwiesen")=COUNTA($H$14:$H$14),"verwiesen",IF(COUNTIF($H$14:$H$14,"nein")+COUNTIF($H$14:$H$14,"entbehrlich")=COUNTA($H$14:$H$14),"nein",IF(COUNTIF($H$14:$H$14,"ja")+COUNTIF($H$14:$H$14,"entbehrlich")+COUNTIF($H$14:$H$14,"verwiesen")=COUNTA($H$14:$H$14),"ja","teilweise")))))) | M13: Vertraulichkeit, Integrität | N13: APP.4.4.A7-UA.1; INF.14.A13-UA.1; INF.14.A6-UA.1; NET.1.1.A19-UA.1; NET.1.1.A22-UA.1; NET.1.1.A23-UA.1; NET.1.1.A23-UA.3; NET.1.1.A31-UA.1; NET.1.1.A33-UA.1; NET.1.1.A34-UA.1; NET.1.1.A4-UA.1; NET.1.1.A5-UA.1; NET.1.1.A5-UA.4; NET.1.1.A6-UA.1; NET.1.2.A33-UA.1; OPS.1.1.1.A15-UA.3; OPS.1.1.2.A16-UA.2; SYS.1.5.A9-UA.3; SYS.1.5.A9-UA.4; SYS.1.5.A9-UA.5; SYS.2.5.A2-UA.3; SYS.2.6.A4-UA.2; SYS.2.6.A4-UA.3 | O13: subset-of; subset-of; subset-of; subset-of; intersects-with; equivalent-to; subset-of; subset-of; subset-of; subset-of; superset-of; subset-of; subset-of; subset-of; superset-of; subset-of; subset-of; equivalent-to; subset-of; subset-of; subset-of; subset-of; subset-of | P13: Die Aufteilung in Netzsegmente (auch Netzdomänen oder Subnetze genannt) ermöglicht es, verschiedene Zonen mit unterschiedlichen Schutzanforderungen – z. B. Büro-IT, Produktionsnetz, Managementnetz – getrennt zu betrachten und gezielt zu schützen. Relevant sind dabei (falls vorhanden) auch WLANs/SSIDs, IoT-Geräte wie vernetzte Kühlschränke, Hausleittechnik, operative Technologien, Industrielle Steuerungssysteme oder Netze zum Zugriff auf Speichersysteme (Storage Area Network, SAN). Die Anforderung gilt auch, wenn die Systeme nur noch als VMs oder Container existieren. Die Segmentierung kann hier in die virtuelle Netzwerk‑Ebene verlagert werden, sodass die Segmentierung weder vom Hypervisor noch von den Workloads umgangen wird. Die Einteilung in Segmente kann anhand einer Klassifizierung von Netzen erfolgen (z.B. nach Schutzbedarf der dort verarbeiteten Daten oder nach Risikoklassen angeschlossener Systeme) erfolgen. Beispiele hierfür sind Internet-Domäne, Endgeräte-Domäne, Domäne für zentrale Serverdienste, Domäne für Systeme hoher Vertraulichkeit. Alternativ können auch organisatorische Domänen verwendet werden, z. B. Personalwesen, Marketing, Finanzverwaltung, Innere Verwaltung. Die Filterkriterien können sich nach den Sicherheitsanforderungen der jeweiligen Netze im Einzelnen oder nach einer vorgenommenen Klassifikation der Netze richten. Hierzu gehören insbesondere die Anforderungen zur Authentifizierung und Autorisierung von Assets. | Q13: Netze | R13: Netzplan | S13: eine Unterteilung des internen Netzes in Netzsegmente | T13: G 0.23 – Unbefugtes Eindringen in IT-Systeme; G 0.19 – Offenlegung schützenswerter Informationen; G 0.30 – Unberechtigte Nutzung oder Administration von Geräten und Systemen; G 0.47 – Schädliche Seiteneffekte IT-gestützter Angriffe | U13: 2 | V13: 2 | W13: 2 | X13: 1 | Y13: 1
A14: ARCH.2.1 | B14: Netzsegmente | C14: ARCH.2.1 | D14: Standard-Anforderungen | E14: Architektur für Netze SOLLTE eine Unterteilung des internen Netzes in Netzsegmente unter Berücksichtigung der Anforderungen der Institution und des Schutzbedarfes verankern. | H14: unbearbeitet | M14: Vertraulichkeit, Integrität | N14: APP.4.4.A7-UA.1; INF.14.A13-UA.1; INF.14.A6-UA.1; NET.1.1.A19-UA.1; NET.1.1.A22-UA.1; NET.1.1.A23-UA.1; NET.1.1.A23-UA.3; NET.1.1.A31-UA.1; NET.1.1.A33-UA.1; NET.1.1.A34-UA.1; NET.1.1.A4-UA.1; NET.1.1.A5-UA.1; NET.1.1.A5-UA.4; NET.1.1.A6-UA.1; NET.1.2.A33-UA.1; OPS.1.1.1.A15-UA.3; OPS.1.1.2.A16-UA.2; SYS.1.5.A9-UA.3; SYS.1.5.A9-UA.4; SYS.1.5.A9-UA.5; SYS.2.5.A2-UA.3; SYS.2.6.A4-UA.2; SYS.2.6.A4-UA.3 | O14: subset-of; subset-of; subset-of; subset-of; intersects-with; equivalent-to; subset-of; subset-of; subset-of; subset-of; superset-of; subset-of; subset-of; subset-of; superset-of; subset-of; subset-of; equivalent-to; subset-of; subset-of; subset-of; subset-of; subset-of | P14: Die Aufteilung in Netzsegmente (auch Netzdomänen oder Subnetze genannt) ermöglicht es, verschiedene Zonen mit unterschiedlichen Schutzanforderungen – z. B. Büro-IT, Produktionsnetz, Managementnetz – getrennt zu betrachten und gezielt zu schützen. Relevant sind dabei (falls vorhanden) auch WLANs/SSIDs, IoT-Geräte wie vernetzte Kühlschränke, Hausleittechnik, operative Technologien, Industrielle Steuerungssysteme oder Netze zum Zugriff auf Speichersysteme (Storage Area Network, SAN). Die Anforderung gilt auch, wenn die Systeme nur noch als VMs oder Container existieren. Die Segmentierung kann hier in die virtuelle Netzwerk‑Ebene verlagert werden, sodass die Segmentierung weder vom Hypervisor noch von den Workloads umgangen wird. Die Einteilung in Segmente kann anhand einer Klassifizierung von Netzen erfolgen (z.B. nach Schutzbedarf der dort verarbeiteten Daten oder nach Risikoklassen angeschlossener Systeme) erfolgen. Beispiele hierfür sind Internet-Domäne, Endgeräte-Domäne, Domäne für zentrale Serverdienste, Domäne für Systeme hoher Vertraulichkeit. Alternativ können auch organisatorische Domänen verwendet werden, z. B. Personalwesen, Marketing, Finanzverwaltung, Innere Verwaltung. Die Filterkriterien können sich nach den Sicherheitsanforderungen der jeweiligen Netze im Einzelnen oder nach einer vorgenommenen Klassifikation der Netze richten. Hierzu gehören insbesondere die Anforderungen zur Authentifizierung und Autorisierung von Assets. | Q14: Netze | R14: Netzplan | S14: eine Unterteilung des internen Netzes in Netzsegmente | T14: G 0.23 – Unbefugtes Eindringen in IT-Systeme; G 0.19 – Offenlegung schützenswerter Informationen; G 0.30 – Unberechtigte Nutzung oder Administration von Geräten und Systemen; G 0.47 – Schädliche Seiteneffekte IT-gestützter Angriffe | U14: 2 | V14: 2 | W14: 2 | X14: 1 | Y14: 1
A15: ARCH.2.2 | B15: Einschränkung von Verbindungen zwischen Segmenten | D15: Standard-Anforderungen | E15: Gesamt: | H15: =IF(OR(COUNTBLANK($H$16:$H$28)>0,COUNTIF($H$16:$H$28,"unbearbeitet")=COUNTA($H$16:$H$28)),"Bitte Teilanforderungen ausfüllen",IF(COUNTIF($H$16:$H$28,"zu klären")>0,"zu klären",IF(COUNTIF($H$16:$H$28,"entbehrlich")=COUNTA($H$16:$H$28),"entbehrlich",IF(COUNTIF($H$16:$H$28,"verwiesen")=COUNTA($H$16:$H$28),"verwiesen",IF(COUNTIF($H$16:$H$28,"nein")+COUNTIF($H$16:$H$28,"entbehrlich")=COUNTA($H$16:$H$28),"nein",IF(COUNTIF($H$16:$H$28,"ja")+COUNTIF($H$16:$H$28,"entbehrlich")+COUNTIF($H$16:$H$28,"verwiesen")=COUNTA($H$16:$H$28),"ja","teilweise")))))) | N15: APP.4.4.A18-UA.3; INF.10.A6-UA.1; INF.10.A6-UA.3; INF.10.A6-UA.6; INF.14.A11-UA.3; INF.14.A11-UA.5; INF.14.A13-UA.2; NET.1.1.A10-UA.2; NET.1.1.A22-UA.6; NET.1.1.A23-UA.2; NET.1.1.A24-UA.1; NET.1.1.A4-UA.4; NET.1.1.A5-UA.4; NET.1.2.A11-UA.8; NET.3.2.A2-UA.3; NET.3.4.A14-UA.2; NET.3.4.A9-UA.2; OPS.1.1.7.A17-UA.1; SYS.1.5.A15-UA.2; SYS.1.5.A9-UA.4; SYS.4.1.A11-UA.2; SYS.4.4.A5-UA.4 | O15: subset-of; subset-of; subset-of; subset-of; subset-of; subset-of; subset-of; subset-of; superset-of; intersects-with; subset-of; intersects-with; subset-of; superset-of; equivalent-to; intersects-with; subset-of; intersects-with; subset-of; equivalent-to; intersects-with; subset-of | P15: Dient dem Ziel, die Angriffsfläche innerhalb interner und externer Netze zu reduzieren und die Ausbreitung potenzieller Schadsoftware oder unberechtigter Zugriffe einzudämmen. Ohne solche Begrenzungen könnte ein einzelner kompromittierter Bereich direkten Zugriff auf weitere sensible Segmente erhalten und dadurch Geschäftsprozesse massiv beeinträchtigen. Beispielsweise benötigt ein Endgerät Verbindungen zu internen Servern und Druckern, während Gäste lediglich auf den Internetanschluss Zugriff benötigen. Im Blick auf weitreichende Sicherheitsvorfälle ist hier insbesondere die Trennung interner Netzsegmente vom Internet zu beachten. Diese Regeln können auf Kriterien wie Gerätetyp (z. B. Laptop, IoT-Gerät), Benutzerrolle (z. B. Administrator, Gast), physischem Anschlussort oder Uhrzeit basieren. Eine klare Trennung von Benutzergruppen über VLANs oder dynamische ACLs erhöht die Sicherheit und Transparenz. Für die Einführung in eine bestehende Umgebung kann ein gestuftes Vorgehen gewählt werden: (1) Zunächst wird ein Überwachungsmodus ("Audit-Only") aktiviert, der protokolliert, welche Zugriffe durch eine strengere Richtlinie verweigert würden, ohne sie tatsächlich zu blockieren. (2) Anschließend werden diese Protokolle analysiert, um legitime, für den Geschäftsbetrieb notwendige Zugriffe zu identifizieren und diese gezielt in die jeweiligen Rollen und Berechtigungsgruppen aufzunehmen. (3) Erst wenn keine legitimen Zugriffe mehr in den Protokollen als "verweigert" auftauchen, wird die Richtlinie scharf geschaltet und blockiert aktiv alle nicht explizit erlaubten Zugriffe. | Q15: Netze | R15: Netzplan | S15: Verbindungen zwischen Netzsegmenten | T15: G 0.23 – Unbefugtes Eindringen in IT-Systeme; G 0.47 – Schädliche Seiteneffekte IT-gestützter Angriffe; G 0.40 – Verhinderung von Diensten (Denial of Service) | U15: 2 | V15: 1 | W15: 1 | X15: 1 | Y15: 0
A16: ARCH.2.2 | B16: Einschränkung von Verbindungen zwischen Segmenten | C16: ARCH.2.2 | D16: Standard-Anforderungen | E16: Architektur für Netze SOLLTE Verbindungen zwischen Netzsegmenten anhand von Kriterien einschränken. | H16: unbearbeitet | N16: APP.4.4.A18-UA.3; INF.10.A6-UA.1; INF.10.A6-UA.3; INF.10.A6-UA.6; INF.14.A11-UA.3; INF.14.A11-UA.5; INF.14.A13-UA.2; NET.1.1.A10-UA.2; NET.1.1.A22-UA.6; NET.1.1.A23-UA.2; NET.1.1.A24-UA.1; NET.1.1.A4-UA.4; NET.1.1.A5-UA.4; NET.1.2.A11-UA.8; NET.3.2.A2-UA.3; NET.3.4.A14-UA.2; NET.3.4.A9-UA.2; OPS.1.1.7.A17-UA.1; SYS.1.5.A15-UA.2; SYS.1.5.A9-UA.4; SYS.4.1.A11-UA.2; SYS.4.4.A5-UA.4 | O16: subset-of; subset-of; subset-of; subset-of; subset-of; subset-of; subset-of; subset-of; superset-of; intersects-with; subset-of; intersects-with; subset-of; superset-of; equivalent-to; intersects-with; subset-of; intersects-with; subset-of; equivalent-to; intersects-with; subset-of | P16: Dient dem Ziel, die Angriffsfläche innerhalb interner und externer Netze zu reduzieren und die Ausbreitung potenzieller Schadsoftware oder unberechtigter Zugriffe einzudämmen. Ohne solche Begrenzungen könnte ein einzelner kompromittierter Bereich direkten Zugriff auf weitere sensible Segmente erhalten und dadurch Geschäftsprozesse massiv beeinträchtigen. Beispielsweise benötigt ein Endgerät Verbindungen zu internen Servern und Druckern, während Gäste lediglich auf den Internetanschluss Zugriff benötigen. Im Blick auf weitreichende Sicherheitsvorfälle ist hier insbesondere die Trennung interner Netzsegmente vom Internet zu beachten. Diese Regeln können auf Kriterien wie Gerätetyp (z. B. Laptop, IoT-Gerät), Benutzerrolle (z. B. Administrator, Gast), physischem Anschlussort oder Uhrzeit basieren. Eine klare Trennung von Benutzergruppen über VLANs oder dynamische ACLs erhöht die Sicherheit und Transparenz. Für die Einführung in eine bestehende Umgebung kann ein gestuftes Vorgehen gewählt werden: (1) Zunächst wird ein Überwachungsmodus ("Audit-Only") aktiviert, der protokolliert, welche Zugriffe durch eine strengere Richtlinie verweigert würden, ohne sie tatsächlich zu blockieren. (2) Anschließend werden diese Protokolle analysiert, um legitime, für den Geschäftsbetrieb notwendige Zugriffe zu identifizieren und diese gezielt in die jeweiligen Rollen und Berechtigungsgruppen aufzunehmen. (3) Erst wenn keine legitimen Zugriffe mehr in den Protokollen als "verweigert" auftauchen, wird die Richtlinie scharf geschaltet und blockiert aktiv alle nicht explizit erlaubten Zugriffe. | Q16: Netze | R16: Netzplan | S16: Verbindungen zwischen Netzsegmenten | T16: G 0.23 – Unbefugtes Eindringen in IT-Systeme; G 0.47 – Schädliche Seiteneffekte IT-gestützter Angriffe; G 0.40 – Verhinderung von Diensten (Denial of Service) | U16: 2 | V16: 1 | W16: 1 | X16: 1 | Y16: 0
A17: ARCH.2.2 | B17: Einschränkung von Verbindungen zwischen Segmenten | C17: ARCH.2.2.1 | D17: Standard-Anforderungen | E17: Architektur für Netze SOLLTE Verbindungen über externe Netzanschlüsse einschränken. | H17: unbearbeitet | M17: Vertraulichkeit, Verfügbarkeit | N17: CON.7.A7-UA.1; IND.2.1.A16-UA.1; INF.10.A6-UA.1; INF.10.A6-UA.3; INF.10.A6-UA.4; INF.10.A6-UA.5; INF.10.A6-UA.6; INF.14.A11-UA.1; INF.14.A11-UA.3; INF.14.A28-UA.2; NET.1.1.A18-UA.1; NET.3.1.A18-UA.2; NET.3.2.A19-UA.1; NET.3.2.A2-UA.3; NET.3.3.A11-UA.1; NET.3.4.A14-UA.2; NET.3.4.A9-UA.2; NET.4.2.A4-UA.2; OPS.1.2.5.A8-UA.4; SYS.1.5.A9-UA.4; SYS.3.2.1.A28-UA.2; SYS.4.1.A11-UA.2; SYS.4.4.A5-UA.4 | O17: subset-of; subset-of; subset-of; subset-of; intersects-with; subset-of; subset-of; subset-of; subset-of; subset-of; superset-of; subset-of; subset-of; subset-of; subset-of; superset-of; subset-of; subset-of; subset-of; superset-of; subset-of; intersects-with; subset-of | P17: Dient dazu, die Angriffsfläche zu reduzieren, unerwünschte Ein- und Ausleitungen zu begrenzen und das Risiko von Datenabflüssen zu minimieren. Für mobile Systeme kann dies z. B. über das Erzwingen einer VPN-Verbindung ins gefilterte Netz der Institution oder über die Verwendung eines direkten Internetzugangs erfolgen, welcher über einen Direct-Internet-Access Agenten abgesichert ist. | Q17: Netze | R17: Netzplan | S17: Verbindungen über externe Netzanschlüsse | T17: G 0.14 – Ausspähen von Informationen (Spionage); G 0.23 – Unbefugtes Eindringen in IT-Systeme; G 0.39 – Schadprogramme; G 0.40 – Verhinderung von Diensten (Denial of Service); G 0.9 – Ausfall oder Störung von Kommunikationsnetzen; G 0.47 – Schädliche Seiteneffekte IT-gestützter Angriffe | U17: 2 | V17: 2 | W17: 1 | X17: 2 | Y17: 0
A18: ARCH.2.2 | B18: Einschränkung von Verbindungen zwischen Segmenten | C18: ARCH.2.2.2 | D18: Standard-Anforderungen | E18: Architektur für Netze SOLLTE Verbindungen zwischen Gastnetz und internem Netz einschränken. | H18: unbearbeitet | N18: INF.10.A1-UA.4; INF.10.A6-UA.1; INF.10.A6-UA.3; INF.10.A6-UA.4; INF.10.A6-UA.6; NET.1.1.A22-UA.6; NET.1.1.A5-UA.4; NET.3.2.A2-UA.2; NET.3.4.A14-UA.2; NET.3.4.A9-UA.2 | O18: subset-of; equivalent-to; equal-to; intersects-with; subset-of; superset-of; superset-of; intersects-with; intersects-with; intersects-with | P18: Wenn Gäste der Institution sich mit dem internen Netz verbinden, könnten Schadprogramme in das Netz gelangen oder unbeabsichtigte Datenflüsse über die Verbindung fließen. Daher ist es sinnvoll, einen vom übrigen Netz getrennten Gastzugang einzurichten, z.B. in Besprechungs-, Veranstaltungs- und Schulungsräumen. Wenn die Einschränkungen von Gastnetzen lockerer sind als die interner Netze am gleichen Standort, so zeigt die Erfahrung, dass auch interne Mitarbeitende gerne auf Gastnetze zurückgreifen. Dadurch könnte es zur Umgehung der internen Schutzmaßnahmen kommen. Daher ist es empfehlenswert, für das Gastnetz gleiche oder strengere Einschränkungen zu wählen oder die Nutzung des Gastnetzes durch Mitarbeitende technisch oder organisatorisch zu beschränken. | Q18: Netze | R18: Netzplan | S18: Verbindungen zwischen Gastnetz und internem Netz | T18: G 0.23 – Unbefugtes Eindringen in IT-Systeme | U18: 2 | V18: 1 | W18: 1 | X18: 0 | Y18: 0
A19: ARCH.2.2 | B19: Einschränkung von Verbindungen zwischen Segmenten | C19: ARCH.2.2.3 | D19: Standard-Anforderungen | E19: Architektur für Netze SOLLTE Verbindungen zwischen Hostsystemen und Clients einschränken. | H19: unbearbeitet | N19: NET.1.1.A19-UA.1; NET.1.1.A5-UA.1; NET.1.1.A5-UA.2; NET.1.1.A5-UA.3; NET.3.4.A9-UA.2; SYS.1.5.A9-UA.4; SYS.2.1.A23-UA.1; SYS.2.5.A2-UA.3 | O19: equivalent-to; equivalent-to; equivalent-to; intersects-with; subset-of; equivalent-to; intersects-with; equivalent-to | P19: Die Anforderung gilt auch, wenn die IT-Systeme nur noch als VMs oder Container existieren. Die Segmentierung kann hier in die virtuelle Netzwerk‑Ebene verlagert werden, sodass die Segmentierung weder vom Hypervisor noch von den Workloads umgangen wird. Die Anforderung kann auch physisch durch dedizierte Infrastruktur für VDI/Client‑VMs umgesetzt werden. Um die klare Trennung sicherzustellen, wird empfohlen kein Bridging zwischen Port‑Groups sowie auf dem virtuellen Switch keinen promiscuous Mode zu verwenden. | Q19: Netze | R19: Netzplan | S19: Verbindungen zwischen Hostsystemen und Clients | T19: G 0.23 – Unbefugtes Eindringen in IT-Systeme; G 0.9 – Ausfall oder Störung von Kommunikationsnetzen; G 0.40 – Verhinderung von Diensten (Denial of Service) | U19: 3 | V19: 1 | W19: 1 | X19: 1 | Y19: 0
A20: ARCH.2.2 | B20: Einschränkung von Verbindungen zwischen Segmenten | C20: ARCH.2.2.4 | D20: Anforderungen bei erhöhtem Schutzbedarf | E20: Architektur für Netze KANN Verbindungen zwischen Daten- und VoIP-Systemen einschränken. | H20: unbearbeitet | M20: Verfügbarkeit | N20: INF.10.A6-UA.6; NET.4.2.A1-UA.5; NET.4.2.A16-UA.1; NET.4.2.A16-UA.2; NET.4.2.A16-UA.3; NET.4.2.A4-UA.2; NET.4.2.A4-UA.3 | O20: intersects-with; intersects-with; equal-to; intersects-with; equivalent-to; intersects-with; subset-of | P20: Werden sowohl Telefonie als auch andere Daten über dasselbe Netz geführt, so könnte dies bei einem Netzausfall dazu führen, dass keine Kommunikation mehr möglich ist, auch nicht zur Meldung oder Behebung der Störung. Die Wahrscheinlichkeit kann durch getrennt betriebene Voice- und Datennetze verringert werden. Für weitere Details siehe „Kompendium für organisationsinterne Telekommunikationssysteme mit erhöhtem Schutzbedarf". | Q20: Netze | R20: Netzplan | S20: Verbindungen zwischen Daten- und VoIP-Systemen | T20: G 0.23 – Unbefugtes Eindringen in IT-Systeme; G 0.9 – Ausfall oder Störung von Kommunikationsnetzen; G 0.40 – Verhinderung von Diensten (Denial of Service) | U20: 5 | V20: 1 | W20: 1 | X20: 2 | Y20: 0
A21: ARCH.2.2 | B21: Einschränkung von Verbindungen zwischen Segmenten | C21: ARCH.2.2.5 | D21: Standard-Anforderungen | E21: Architektur für Netze SOLLTE Verbindungen zwischen OT-Systemen und anderen IT-Systemen einschränken. | H21: unbearbeitet | M21: Verfügbarkeit | N21: IND.1.A8-UA.1; IND.2.4.A1-UA.5; IND.3.2.A12-UA.1; IND.3.2.A5-UA.1; IND.3.2.A7-UA.1; IND.3.2.A7-UA.2; IND.3.2.A7-UA.4; IND.3.2.A8-UA.5; INF.14.A18-UA.1 | O21: subset-of; subset-of; intersects-with; intersects-with; subset-of; subset-of; subset-of; intersects-with; intersects-with | P21: IT- und OT-Systeme haben typischerweise sehr unterschiedliche Risikoprofile (IT: Schnelllebig, viele Cybersicherheitsmechanismen, OT: Stabilität, weniger Cybersicherheitsmechanismen, beispielsweise industrielle Steuerungssysteme und Gebäudeautomationstechnik). Insbesondere der Zugriff auf OT-Funktionen (z. B. Öffnung zentraler Schließanlage) ist mit erhöhtem Risiko verbunden und könnte auch versehentlich z.B. durch Portscanner ausgelöst werden. Stattdessen ist es empfehlenswert, den Zugriff zu solchen Netzen nur über dafür vorgesehene Quellen zu ermöglichen (z. B. Sprungserver, bestimmte auslösende OT-Systeme). | Q21: Netze | R21: Netzplan | S21: Verbindungen zwischen OT-Systemen und anderen IT-Systemen | T21: G 0.23 – Unbefugtes Eindringen in IT-Systeme; G 0.9 – Ausfall oder Störung von Kommunikationsnetzen; G 0.40 – Verhinderung von Diensten (Denial of Service) | U21: 3 | V21: 1 | W21: 1 | X21: 2 | Y21: 0
A22: ARCH.2.2 | B22: Einschränkung von Verbindungen zwischen Segmenten | C22: ARCH.2.2.6 | D22: Standard-Anforderungen | E22: Architektur für Netze SOLLTE eine demilitarisierte Zone installieren. | H22: unbearbeitet | M22: Vertraulichkeit, Integrität | N22: APP.3.6.A16-UA.2; IND.1.A16-UA.2; NET.1.1.A10-UA.1; NET.1.1.A10-UA.2; NET.1.1.A10-UA.3; NET.1.1.A4-UA.1 | O22: subset-of; intersects-with; subset-of; subset-of; subset-of; equal-to | P22: Unter einer Demilitarisierten Zone versteht man in diesem Kontext ein logisch oder physisch getrenntes Teilnetz, in dem Systeme mit exponierten Diensten – wie Webserver, Mail-Gateways oder VPN-Endpunkte – betrieben werden. Systeme der Institution, die sowohl aus dem öffentlichen Netz als auch aus dem internen Netz erreichbar sind, werden in einer demilitarisierten Zone (DMZ) so betrieben, dass (1) der Netzverkehr zwischen dem System und dem öffentlichen Netz gefiltert wird und (2) der Netzverkehr zwischen dem System und anderen internen Netzen gefiltert wird. Eine DMZ kann sowohl durch dedizierte Hardware-Firewalls als auch durch virtuelle Netzwerksegmente umgesetzt werden. Ohne eine solche Trennung könnte ein kompromittierter Webserver direkt als Sprungbrett ins interne Netz dienen oder Schadsoftware könnte sich ungehindert auf sensible Systeme ausbreiten. Mit einer DMZ kann eine Institution hingegen erreichen, dass kompromittierte Systeme isoliert bleiben und sicherheitskritische interne Netze weiterhin geschützt sind. | Q22: Netze | R22: Netzplan | S22: eine demilitarisierte Zone | T22: G 0.23 – Unbefugtes Eindringen in IT-Systeme; G 0.47 – Schädliche Seiteneffekte IT-gestützter Angriffe | U22: 3 | V22: 2 | W22: 2 | X22: 1 | Y22: 0
A23: ARCH.2.2 | B23: Einschränkung von Verbindungen zwischen Segmenten | C23: ARCH.2.2.7 | D23: Standard-Anforderungen | E23: Architektur für Netze SOLLTE ein oder mehrere Management-Netze installieren. | H23: unbearbeitet | M23: Vertraulichkeit | N23: NET.1.1.A21-UA.5; NET.1.2.A28-UA.2; NET.1.2.A29-UA.1; NET.1.2.A33-UA.1; NET.3.1.A13-UA.1; NET.3.1.A4-UA.4; NET.3.1.A4-UA.5; NET.3.2.A18-UA.1; NET.3.2.A18-UA.3; OPS.1.1.2.A16-UA.2; SYS.1.5.A11-UA.1; SYS.1.5.A5-UA.1; SYS.1.5.A9-UA.3; SYS.1.6.A5-UA.1 | O23: equivalent-to; intersects-with; subset-of; subset-of; subset-of; subset-of; intersects-with; subset-of; intersects-with; equivalent-to; subset-of; intersects-with; superset-of; subset-of | P23: Ein Management-Netz ist ein physisch oder durch Netzfilter separiertes Netzsegment, das dediziert für die Überwachung, Verwaltung und Wartung von IT-Systemen bestimmt ist. Es ist von anderen Produktions- und Datennetzen getrennt, um den Zugriff auf kritische Verwaltungsfunktionen zu schützen und die Verfügbarkeit dieser Zugänge auch bei Problemen im restlichen Netz zu sichern. Dies gilt auch für virtualisierte Systeme. Im Kontext der Containerisierung empfiehlt es sich, administrative Zugänge auf Applikations-Container immer über die Container-Runtime erfolgen zu lassen. | Q23: Netze | R23: Netzplan | S23: ein oder mehrere Management-Netze | T23: G 0.30 – Unberechtigte Nutzung oder Administration von Geräten und Systemen; G 0.23 – Unbefugtes Eindringen in IT-Systeme; G 0.32 – Missbrauch von Berechtigungen; G 0.19 – Offenlegung schützenswerter Informationen | U23: 3 | V23: 2 | W23: 1 | X23: 1 | Y23: 1
A24: ARCH.2.2 | B24: Einschränkung von Verbindungen zwischen Segmenten | C24: ARCH.2.2.8 | D24: Standard-Anforderungen | E24: Architektur für Netze SOLLTE Verbindungen zwischen Testumgebungen und Betrieb einschränken. | H24: unbearbeitet | M24: Vertraulichkeit, Integrität | N24: CON.8.A7-UA.8; NET.3.4.A9-UA.2; OPS.1.1.3.A9-UA.3; OPS.1.1.6.A13-UA.1; OPS.1.1.6.A13-UA.2; SYS.1.5.A9-UA.4; SYS.1.7.A33-UA.1 | O24: subset-of; intersects-with; subset-of; subset-of; equal-to; superset-of; subset-of | P24: Entwicklungs-, Staging- und Testumgebungen haben oft geringere Sicherheitsvorkehrungen als Produktivsysteme. Eine saubere Trennung zwischen Test- und Produktivumgebung verhindert Übergriffe auf das Produktivsystem und vermeidet Ressourcenkonflikte. | Q24: Netze | R24: Netzplan | S24: Verbindungen zwischen Testumgebungen und Betrieb | T24: G 0.23 – Unbefugtes Eindringen in IT-Systeme; G 0.26 – Fehlfunktion von Geräten oder Systemen; G 0.20 – Informationen oder Produkte aus unzuverlässiger Quelle; G 0.28 – Software-Schwachstellen oder -Fehler | U24: 4 | V24: 2 | W24: 2 | X24: 1 | Y24: 1
A25: ARCH.2.2 | B25: Einschränkung von Verbindungen zwischen Segmenten | C25: ARCH.2.2.9 | D25: Standard-Anforderungen | E25: Architektur für Netze SOLLTE Verbindungen zwischen IPv4 und IPv6 einschränken. | H25: unbearbeitet | M25: Vertraulichkeit, Integrität | N25: NET.1.1.A20-UA.1; NET.3.2.A17-UA.1; NET.3.4.A9-UA.2 | O25: equivalent-to; subset-of; intersects-with | P25: IPv4 und IPv6 sind grundlegende Netzprotokolle, die unterschiedliche Protokollstacks und Sicherheitseigenschaften haben. Eine Trennung von IT-Systemen mit IPv4 und IPv6 erschwert es Angreifern, Schwachstellen der Protokolle auszunutzen oder zu kombinieren und verringert die Wahrscheinlichkeit von Fehlern durch Wechselwirkungen. | Q25: Netze | R25: Netzplan | S25: Verbindungen zwischen IPv4 und IPv6 | T25: G 0.23 – Unbefugtes Eindringen in IT-Systeme; G 0.18 – Fehlplanung oder fehlende Anpassung; G 0.39 – Schadprogramme | U25: 4 | V25: 2 | W25: 2 | X25: 1 | Y25: 0
A26: ARCH.2.2 | B26: Einschränkung von Verbindungen zwischen Segmenten | C26: ARCH.2.2.10 | D26: Standard-Anforderungen | E26: Architektur für Netze SOLLTE Verbindungen zwischen Druckern und anderen Systemen einschränken. | H26: unbearbeitet | N26: NET.3.4.A9-UA.2; SYS.1.5.A9-UA.4; SYS.4.1.A11-UA.1; SYS.4.1.A11-UA.3; SYS.4.1.A18-UA.3; SYS.4.1.A4-UA.1 | O26: intersects-with; superset-of; subset-of; subset-of; subset-of; intersects-with | P26: Drucker können Schwachstellen aufweisen, die Angreifer ausnutzen, z.B. veraltete Firmware oder ungesicherte Netzprotokolle. Durch die Segmentierung wird die Angriffsoberfläche reduziert und die Netzüberwachung erleichtert. Die Umsetzung kann physisch oder durch VLANs erfolgen. | Q26: Netze | R26: Netzplan | S26: Verbindungen zwischen Druckern und anderen Systemen | T26: G 0.30 – Unberechtigte Nutzung oder Administration von Geräten und Systemen; G 0.18 – Fehlplanung oder fehlende Anpassung; G 0.39 – Schadprogramme | U26: 4 | V26: 1 | W26: 1 | X26: 1 | Y26: 1
A27: ARCH.2.2 | B27: Einschränkung von Verbindungen zwischen Segmenten | C27: ARCH.2.2.11 | D27: Anforderungen bei erhöhtem Schutzbedarf | E27: Architektur für Netze KANN den physischen Zugang auf diese einschränken. | H27: unbearbeitet | N27: NET.1.1.A23-UA.4; NET.1.1.A31-UA.1; NET.1.1.A32-UA.1; NET.1.1.A4-UA.1; NET.1.2.A32-UA.1; OPS.1.1.7.A21-UA.1 | O27: intersects-with; subset-of; subset-of; superset-of; subset-of; subset-of | P27: Obwohl sich eine virtuelle Vernetzung immer größerer Beliebtheit erfreut, können Konfigurationsfehler oder Sicherheitslücken dabei leichter zu einer Umgehung der Netztrennung führen, als wenn die Netze bereits auf physischer Ebene voneinander getrennt werden. | Q27: Netze | R27: Netzplan | S27: den physischen Zugang auf diese | T27: G 0.18 – Fehlplanung oder fehlende Anpassung; G 0.29 – Verstoß gegen Gesetze oder Regelungen; G 0.23 – Unbefugtes Eindringen in IT-Systeme; G 0.9 – Ausfall oder Störung von Kommunikationsnetzen | U27: 5 | V27: 1 | W27: 1 | X27: 1 | Y27: 0
A28: ARCH.2.2 | B28: Einschränkung von Verbindungen zwischen Segmenten | C28: ARCH.2.2.12 | D28: Anforderungen bei erhöhtem Schutzbedarf | E28: Architektur KANN Sprungserver installieren. | H28: unbearbeitet | M28: Vertraulichkeit | N28: IND.3.2.A7-UA.4; NET.1.2.A21-UA.3; OPS.1.1.7.A26-UA.1; OPS.1.2.5.A25-UA.3 | O28: superset-of; intersects-with; equivalent-to; equivalent-to | P28: Ein Sprungserver (englisch „jump server“ oder „jump host“) ist ein speziell abgesicherter Server, der als einzig vorgesehener Einstiegspunkt in ein Verwaltungsnetz oder zu administrierten Systemen dient. Alle administrativen Sitzungen laufen über diesen zentralen Knotenpunkt, wodurch die Angriffsfläche reduziert und die Nachvollziehbarkeit erhöht wird. Ohne Sprungserver könnte ein Angreifer beispielsweise über kompromittierte Administrator-Notebooks unbemerkt direkt auf zentrale Systeme zugreifen und dort Manipulationen durchführen. Ein Sprungserver kann hingegen alle Management-Zugriffe zentral kanalisieren, sodass verdächtige Aktivitäten leichter erkannt und im Nachhinein nachvollzogen werden können. Praktische Umsetzungen können sein: (1) der Einsatz eines dedizierten, gehärteten Servers mit restriktiven Firewall-Regeln, (2) die Nutzung von Mehrfaktor-Authentisierung und zentralem Benutzer-Management auf dem Sprungserver, (3) eine verpflichtende Session-Aufzeichnung oder Protokollierung sämtlicher Administrationsvorgänge. | R28: Netzplan | S28: Sprungserver | T28: G 0.23 – Unbefugtes Eindringen in IT-Systeme; G 0.30 – Unberechtigte Nutzung oder Administration von Geräten und Systemen; G 0.15 – Abhören | U28: 5 | V28: 2 | W28: 1 | X28: 1 | Y28: 1
A29: ARCH.2.3 | B29: Mikrosegmentierung | D29: Anforderungen bei erhöhtem Schutzbedarf | E29: Gesamt: | H29: =IF(OR(COUNTBLANK($H$30:$H$30)>0,COUNTIF($H$30:$H$30,"unbearbeitet")=COUNTA($H$30:$H$30)),"Bitte Teilanforderungen ausfüllen",IF(COUNTIF($H$30:$H$30,"zu klären")>0,"zu klären",IF(COUNTIF($H$30:$H$30,"entbehrlich")=COUNTA($H$30:$H$30),"entbehrlich",IF(COUNTIF($H$30:$H$30,"verwiesen")=COUNTA($H$30:$H$30),"verwiesen",IF(COUNTIF($H$30:$H$30,"nein")+COUNTIF($H$30:$H$30,"entbehrlich")=COUNTA($H$30:$H$30),"nein",IF(COUNTIF($H$30:$H$30,"ja")+COUNTIF($H$30:$H$30,"entbehrlich")+COUNTIF($H$30:$H$30,"verwiesen")=COUNTA($H$30:$H$30),"ja","teilweise")))))) | M29: Vertraulichkeit | N29: NET.1.1.A4-UA.3; NET.3.4.A9-UA.2; SYS.1.5.A4-UA.2; SYS.1.5.A9-UA.4; SYS.1.6.A5-UA.3 | O29: subset-of; equivalent-to; subset-of; subset-of; equivalent-to | P29: Mikrosegmentierung ist die Unterteilung des Netzes in möglichst kleine Segmente (z.B. pro IT-System oder Server-Anwendung). Für jedes dieser Segmente wird die erlaubte Kommunikation definiert und gefiltert. Mikrosegmentierung sorgt dafür, dass z.B. zwei medizinische Geräte mit gleicher Rolle zwar ins gleiche VLAN dürfen, aber nicht direkt miteinander kommunizieren dürfen. Die Umsetzung kann mit dynamischen VLANs, softwaredefinierten Netzwerken (SDN) oder Netzwerk-Firewalls auf Host-Ebene erfolgen. Die Mikrosegmentierung begrenzt Angriffe, die sich lateral ausbreiten. | Q29: IT-Systeme | R29: Netzplan | S29: Verbindungen zu allen anderen IT-Systemen | T29: G 0.23 – Unbefugtes Eindringen in IT-Systeme; G 0.30 – Unberechtigte Nutzung oder Administration von Geräten und Systemen; G 0.15 – Abhören | U29: 5 | V29: 2 | W29: 1 | X29: 1 | Y29: 1
A30: ARCH.2.3 | B30: Mikrosegmentierung | C30: ARCH.2.3 | D30: Anforderungen bei erhöhtem Schutzbedarf | E30: Architektur für IT-Systeme KANN Verbindungen zu allen anderen IT-Systemen einschränken. | H30: unbearbeitet | M30: Vertraulichkeit | N30: NET.1.1.A4-UA.3; NET.3.4.A9-UA.2; SYS.1.5.A4-UA.2; SYS.1.5.A9-UA.4; SYS.1.6.A5-UA.3 | O30: subset-of; equivalent-to; subset-of; subset-of; equivalent-to | P30: Mikrosegmentierung ist die Unterteilung des Netzes in möglichst kleine Segmente (z.B. pro IT-System oder Server-Anwendung). Für jedes dieser Segmente wird die erlaubte Kommunikation definiert und gefiltert. Mikrosegmentierung sorgt dafür, dass z.B. zwei medizinische Geräte mit gleicher Rolle zwar ins gleiche VLAN dürfen, aber nicht direkt miteinander kommunizieren dürfen. Die Umsetzung kann mit dynamischen VLANs, softwaredefinierten Netzwerken (SDN) oder Netzwerk-Firewalls auf Host-Ebene erfolgen. Die Mikrosegmentierung begrenzt Angriffe, die sich lateral ausbreiten. | Q30: IT-Systeme | R30: Netzplan | S30: Verbindungen zu allen anderen IT-Systemen | T30: G 0.23 – Unbefugtes Eindringen in IT-Systeme; G 0.30 – Unberechtigte Nutzung oder Administration von Geräten und Systemen; G 0.15 – Abhören | U30: 5 | V30: 2 | W30: 1 | X30: 1 | Y30: 1
A31: ARCH.2.4 | B31: Inventar der Netze | D31: Standard-Anforderungen | E31: Gesamt: | H31: =IF(OR(COUNTBLANK($H$32:$H$32)>0,COUNTIF($H$32:$H$32,"unbearbeitet")=COUNTA($H$32:$H$32)),"Bitte Teilanforderungen ausfüllen",IF(COUNTIF($H$32:$H$32,"zu klären")>0,"zu klären",IF(COUNTIF($H$32:$H$32,"entbehrlich")=COUNTA($H$32:$H$32),"entbehrlich",IF(COUNTIF($H$32:$H$32,"verwiesen")=COUNTA($H$32:$H$32),"verwiesen",IF(COUNTIF($H$32:$H$32,"nein")+COUNTIF($H$32:$H$32,"entbehrlich")=COUNTA($H$32:$H$32),"nein",IF(COUNTIF($H$32:$H$32,"ja")+COUNTIF($H$32:$H$32,"entbehrlich")+COUNTIF($H$32:$H$32,"verwiesen")=COUNTA($H$32:$H$32),"ja","teilweise")))))) | M31: Vertraulichkeit, Integrität | N31: IND.1.A4-UA.6; INF.12.A10-UA.1; NET.1.1.A16-UA.2; NET.1.1.A17-UA.2; NET.1.1.A2-UA.5; NET.1.1.A22-UA.4; NET.1.1.A25-UA.1; NET.1.2.A12-UA.6; NET.1.2.A13-UA.2 | O31: subset-of; subset-of; superset-of; superset-of; equivalent-to; superset-of; intersects-with; subset-of; intersects-with | P31: Die Erfassung externer Netzanschlüsse – etwa zu Partnernetzen, Cloud-Diensten oder dem Internet – hilft, potenzielle Angriffspunkte zu identifizieren und gezielte Schutzmaßnahmen zu planen. Beispiele für interne Netzsegmente können klassische Trennungen wie IT-Office-Netze, SCADA-/Leittechnik-Netze oder DMZs für externe Zugriffe sein. Dabei sollten auch virtuelle Netze und virtuelle Switches berücksichtigt werden, ebenso wie Container-Infrastrukturen. Als externe Netzanschlüsse kommen etwa VPN-Gateways, dedizierte Providerverbindungen, Fernwartungszugänge oder Cloud-Endpunkte in Frage. Dabei sind nicht nur die auf den ersten Blick relevanten Datennetze, sondern auch andere Telekommunikationsanbindungen wie ISDN-Leitungen, Mobilfunkausweichstrecken oder WLAN-Roaming von Clients relevant. Der Verwendungszweck beschreibt, warum ein Segment oder Anschluss existiert – etwa für Produktivsysteme, Entwicklung, Administration oder Gastzugänge. Der Zweck von Netzsegmenten kann durch einen sprechenden Namen dokumentiert werden, z. B. Management-Netz, OT-Netz, Internetanschluss, Netz der Finanzverwaltung. Dies hilft, Zuständigkeiten und Zugriffsrechte klar zuzuordnen, z. B. anhand von Geschäftsprozessen, Organisationseinheiten oder Zielgruppen (z. B. Gäste, Vertrieb, Leitung). Dabei sind, falls vorhanden, auch WLANs/SSIDs, IoT-Geräte wie vernetzte Kühlschränke, Hausleittechnik, operative Technologien oder Industrielle Steuerungssysteme zu berücksichtigen. Informationen können aus Netzwerkmanagementsystemen, Konfigurationsdateien oder Asset-Management-Tools gewonnen werden. Die Pflege kann als wiederkehrende Aufgabe in Prozesse eingebettet oder im Rahmen von Änderungen (z. B. Change Management) angestoßen werden. Auch eine einfache Pflege in Tabellenform kann sinnvoll sein – entscheidend ist die Klarheit und Aktualität. | R31: Netzplan | S31: ein Inventar der Netze | T31: G 0.18 – Fehlplanung oder fehlende Anpassung; G 0.23 – Unbefugtes Eindringen in IT-Systeme; G 0.30 – Unberechtigte Nutzung oder Administration von Geräten und Systemen | U31: 2 | V31: 2 | W31: 2 | X31: 1 | Y31: 1
A32: ARCH.2.4 | B32: Inventar der Netze | C32: ARCH.2.4 | D32: Standard-Anforderungen | E32: Architektur SOLLTE ein Inventar der Netze einschließlich interner Segmente, externer Netzanschlüsse und deren Verwendungszweck dokumentieren. | H32: unbearbeitet | M32: Vertraulichkeit, Integrität | N32: IND.1.A4-UA.6; INF.12.A10-UA.1; NET.1.1.A16-UA.2; NET.1.1.A17-UA.2; NET.1.1.A2-UA.5; NET.1.1.A22-UA.4; NET.1.1.A25-UA.1; NET.1.2.A12-UA.6; NET.1.2.A13-UA.2 | O32: subset-of; subset-of; superset-of; superset-of; equivalent-to; superset-of; intersects-with; subset-of; intersects-with | P32: Die Erfassung externer Netzanschlüsse – etwa zu Partnernetzen, Cloud-Diensten oder dem Internet – hilft, potenzielle Angriffspunkte zu identifizieren und gezielte Schutzmaßnahmen zu planen. Beispiele für interne Netzsegmente können klassische Trennungen wie IT-Office-Netze, SCADA-/Leittechnik-Netze oder DMZs für externe Zugriffe sein. Dabei sollten auch virtuelle Netze und virtuelle Switches berücksichtigt werden, ebenso wie Container-Infrastrukturen. Als externe Netzanschlüsse kommen etwa VPN-Gateways, dedizierte Providerverbindungen, Fernwartungszugänge oder Cloud-Endpunkte in Frage. Dabei sind nicht nur die auf den ersten Blick relevanten Datennetze, sondern auch andere Telekommunikationsanbindungen wie ISDN-Leitungen, Mobilfunkausweichstrecken oder WLAN-Roaming von Clients relevant. Der Verwendungszweck beschreibt, warum ein Segment oder Anschluss existiert – etwa für Produktivsysteme, Entwicklung, Administration oder Gastzugänge. Der Zweck von Netzsegmenten kann durch einen sprechenden Namen dokumentiert werden, z. B. Management-Netz, OT-Netz, Internetanschluss, Netz der Finanzverwaltung. Dies hilft, Zuständigkeiten und Zugriffsrechte klar zuzuordnen, z. B. anhand von Geschäftsprozessen, Organisationseinheiten oder Zielgruppen (z. B. Gäste, Vertrieb, Leitung). Dabei sind, falls vorhanden, auch WLANs/SSIDs, IoT-Geräte wie vernetzte Kühlschränke, Hausleittechnik, operative Technologien oder Industrielle Steuerungssysteme zu berücksichtigen. Informationen können aus Netzwerkmanagementsystemen, Konfigurationsdateien oder Asset-Management-Tools gewonnen werden. Die Pflege kann als wiederkehrende Aufgabe in Prozesse eingebettet oder im Rahmen von Änderungen (z. B. Change Management) angestoßen werden. Auch eine einfache Pflege in Tabellenform kann sinnvoll sein – entscheidend ist die Klarheit und Aktualität. | R32: Netzplan | S32: ein Inventar der Netze | T32: G 0.18 – Fehlplanung oder fehlende Anpassung; G 0.23 – Unbefugtes Eindringen in IT-Systeme; G 0.30 – Unberechtigte Nutzung oder Administration von Geräten und Systemen | U32: 2 | V32: 2 | W32: 2 | X32: 1 | Y32: 1
A33: ARCH.2.5 | B33: Netzplan | D33: Standard-Anforderungen | E33: Gesamt: | H33: =IF(OR(COUNTBLANK($H$34:$H$34)>0,COUNTIF($H$34:$H$34,"unbearbeitet")=COUNTA($H$34:$H$34)),"Bitte Teilanforderungen ausfüllen",IF(COUNTIF($H$34:$H$34,"zu klären")>0,"zu klären",IF(COUNTIF($H$34:$H$34,"entbehrlich")=COUNTA($H$34:$H$34),"entbehrlich",IF(COUNTIF($H$34:$H$34,"verwiesen")=COUNTA($H$34:$H$34),"verwiesen",IF(COUNTIF($H$34:$H$34,"nein")+COUNTIF($H$34:$H$34,"entbehrlich")=COUNTA($H$34:$H$34),"nein",IF(COUNTIF($H$34:$H$34,"ja")+COUNTIF($H$34:$H$34,"entbehrlich")+COUNTIF($H$34:$H$34,"verwiesen")=COUNTA($H$34:$H$34),"ja","teilweise")))))) | M33: Vertraulichkeit, Integrität | N33: IND.1.A4-UA.6; NET.1.1.A13-UA.3; NET.1.1.A2-UA.2; NET.1.1.A2-UA.5; NET.1.1.A25-UA.1 | O33: subset-of; intersects-with; equal-to; subset-of; superset-of | P33: Ein Netzplan (engl. network diagram) stellt eine schematische Darstellung der logischen und physischen Struktur von Kommunikationsnetzen dar und bildet die Grundlage für Transparenz im Betrieb. Er kann einen zentralen Beitrag zur Informationssicherheit leisten, da er Transparenz über die Struktur, Verbindungen und Schutzbedarfe einer Netzwerkumgebung schafft. Ein aktueller Netzplan, aus dem sich gut die Netzstruktur erkennen lässt, ermöglicht es Anschlüssen mit hohem Risiko oder von einzelnen Ausfallstellen (Single Points of Failure) auf einen Blick zu erkennen. Für die Umsetzung ist es nicht erforderlich, jedes Subnetz einzeln in einer Grafik zu visualisieren. Vielmehr kann es hilfreich sein, Netzpläne auf einem abstrahierten Level zu halten, z. B. als logische Übersicht mit Domänen, Segmenten und Übergängen (bereinigter Netzplan). Eine Visualisierung als Layer-Modell (z. B. Infrastruktur-, Kommunikations- und Applikationsebene) kann zusätzliche Einblicke schaffen. Auch eine einfache Pflege als visuelle Skizze kann sinnvoll sein – entscheidend ist die Klarheit und Aktualität. | Q33: Netze | R33: Netzplan | S33: einen Netzplan | T33: G 0.23 – Unbefugtes Eindringen in IT-Systeme; G 0.30 – Unberechtigte Nutzung oder Administration von Geräten und Systemen; G 0.18 – Fehlplanung oder fehlende Anpassung; G 0.37 – Abstreiten von Handlungen | U33: 2 | V33: 2 | W33: 2 | X33: 1 | Y33: 1
A34: ARCH.2.5 | B34: Netzplan | C34: ARCH.2.5 | D34: Standard-Anforderungen | E34: Architektur für Netze SOLLTE einen Netzplan dokumentieren. | H34: unbearbeitet | M34: Vertraulichkeit, Integrität | N34: IND.1.A4-UA.6; NET.1.1.A13-UA.3; NET.1.1.A2-UA.2; NET.1.1.A2-UA.5; NET.1.1.A25-UA.1 | O34: subset-of; intersects-with; equal-to; subset-of; superset-of | P34: Ein Netzplan (engl. network diagram) stellt eine schematische Darstellung der logischen und physischen Struktur von Kommunikationsnetzen dar und bildet die Grundlage für Transparenz im Betrieb. Er kann einen zentralen Beitrag zur Informationssicherheit leisten, da er Transparenz über die Struktur, Verbindungen und Schutzbedarfe einer Netzwerkumgebung schafft. Ein aktueller Netzplan, aus dem sich gut die Netzstruktur erkennen lässt, ermöglicht es Anschlüssen mit hohem Risiko oder von einzelnen Ausfallstellen (Single Points of Failure) auf einen Blick zu erkennen. Für die Umsetzung ist es nicht erforderlich, jedes Subnetz einzeln in einer Grafik zu visualisieren. Vielmehr kann es hilfreich sein, Netzpläne auf einem abstrahierten Level zu halten, z. B. als logische Übersicht mit Domänen, Segmenten und Übergängen (bereinigter Netzplan). Eine Visualisierung als Layer-Modell (z. B. Infrastruktur-, Kommunikations- und Applikationsebene) kann zusätzliche Einblicke schaffen. Auch eine einfache Pflege als visuelle Skizze kann sinnvoll sein – entscheidend ist die Klarheit und Aktualität. | Q34: Netze | R34: Netzplan | S34: einen Netzplan | T34: G 0.23 – Unbefugtes Eindringen in IT-Systeme; G 0.30 – Unberechtigte Nutzung oder Administration von Geräten und Systemen; G 0.18 – Fehlplanung oder fehlende Anpassung; G 0.37 – Abstreiten von Handlungen | U34: 2 | V34: 2 | W34: 2 | X34: 1 | Y34: 1
A35: ARCH.2.6 | B35: Topologieüberwachung | D35: Standard-Anforderungen | E35: Gesamt: | H35: =IF(OR(COUNTBLANK($H$36:$H$36)>0,COUNTIF($H$36:$H$36,"unbearbeitet")=COUNTA($H$36:$H$36)),"Bitte Teilanforderungen ausfüllen",IF(COUNTIF($H$36:$H$36,"zu klären")>0,"zu klären",IF(COUNTIF($H$36:$H$36,"entbehrlich")=COUNTA($H$36:$H$36),"entbehrlich",IF(COUNTIF($H$36:$H$36,"verwiesen")=COUNTA($H$36:$H$36),"verwiesen",IF(COUNTIF($H$36:$H$36,"nein")+COUNTIF($H$36:$H$36,"entbehrlich")=COUNTA($H$36:$H$36),"nein",IF(COUNTIF($H$36:$H$36,"ja")+COUNTIF($H$36:$H$36,"entbehrlich")+COUNTIF($H$36:$H$36,"verwiesen")=COUNTA($H$36:$H$36),"ja","teilweise")))))) | N35: NET.1.1.A1-UA.7; NET.1.1.A15-UA.3; NET.1.2.A11-UA.4; NET.2.1.A13-UA.2 | O35: superset-of; equivalent-to; superset-of; subset-of | P35: Unbeabsichtigte Netzverbindungen können z.B. über falsch gesteckte Kabel, WLAN auf Clients oder Modems im öffentlichen Telefonnetz (PSTN) an einer TK-Anlage entstehen. Die Anforderung kann durch Netzscans, Software zur Topologieüberwachung oder Protokollanalyse umgesetzt werden. Hierbei sind auch virtualisierte Systeme auf VM-Hosts zu berücksichtigen. | Q35: Netze | R35: IT-Betriebskonzept | S35: die Einhaltung der Netzarchitektur | T35: G 0.19 – Offenlegung schützenswerter Informationen; G 0.30 – Unberechtigte Nutzung oder Administration von Geräten und Systemen; G 0.22 – Manipulation von Informationen; G 0.41 – Sabotage | U35: 4 | V35: 1 | W35: 1 | X35: 1 | Y35: 1
A36: ARCH.2.6 | B36: Topologieüberwachung | C36: ARCH.2.6 | D36: Standard-Anforderungen | E36: Architektur für Netze SOLLTE die Einhaltung der Netzarchitektur regelmäßig überprüfen. | H36: unbearbeitet | N36: NET.1.1.A1-UA.7; NET.1.1.A15-UA.3; NET.1.2.A11-UA.4; NET.2.1.A13-UA.2 | O36: superset-of; equivalent-to; superset-of; subset-of | P36: Unbeabsichtigte Netzverbindungen können z.B. über falsch gesteckte Kabel, WLAN auf Clients oder Modems im öffentlichen Telefonnetz (PSTN) an einer TK-Anlage entstehen. Die Anforderung kann durch Netzscans, Software zur Topologieüberwachung oder Protokollanalyse umgesetzt werden. Hierbei sind auch virtualisierte Systeme auf VM-Hosts zu berücksichtigen. | Q36: Netze | R36: IT-Betriebskonzept | S36: die Einhaltung der Netzarchitektur | T36: G 0.19 – Offenlegung schützenswerter Informationen; G 0.30 – Unberechtigte Nutzung oder Administration von Geräten und Systemen; G 0.22 – Manipulation von Informationen; G 0.41 – Sabotage | U36: 4 | V36: 1 | W36: 1 | X36: 1 | Y36: 1
